<?xml version="1.0"?>

<robot name="jackal" xmlns:xacro="http://ros.org/wiki/xacro">

    <argument name="is_ignition" default="true" />

    <!-- Include Gazebo Parameters -->
    <xacro:include filename="$(find jackal_playground)/urdf/jackal_gazebo.xacro" />

    <!-- Include ROS2 contol Parameters -->
    <xacro:include filename="$(find jackal_playground)/urdf/jackal_ros2_control.xacro" />


    <link name="base_link"/>

    <!-- Chassis -->

    <link name="chassis_link">
        <visual>
            <origin xyz="0 0 -0.0655" rpy="1.57 0 1.57"/>
            <geometry>
                <mesh filename="package://jackal_playground/meshes/jackal-base.stl"/>
            </geometry>
            <material name="yellow" />
        </visual>
        <collision>
            <origin xyz="0 0 0.092" rpy="0 0 0"/>
            <geometry>
                <box size="0.420 0.310 0.184"/>
            </geometry>
            
        </collision>
        <inertial>
            <!-- Center of mass -->
            <origin xyz="0.012  0.002 0.067" rpy="0 0 0"/>
            <mass value="16.523"/>
            <!-- Moments of inertia: ( chassis without wheels ) -->
            <inertia
                ixx="0.3136" ixy="-0.0008" ixz="0.0164"
                iyy="0.3922" iyz="-0.0009"
                izz="0.4485"/>
        </inertial>
    </link>

    <joint name="base_joint" type="fixed">
      <parent link="base_link" />
      <child link="chassis_link" />
      <axis xyz="0 0 0" />
      <origin rpy="0 0 0" xyz="0 0 0" />
    </joint>

    <!-- Front right wheel -->

    <link name="wheel_front_right_link">
        <visual>
            <origin xyz="0 0 0" rpy="1.57 0 0"/>
            <geometry>
                <mesh filename="package://jackal_playground/meshes/jackal-wheel.stl"/>
            </geometry>
            <material name="black" />
        </visual>
        <collision>
            <origin xyz="0 0 0" rpy="1.57 0 0"/>
            <geometry>
                <cylinder radius="0.098" length="0.040"/>
            </geometry>
        </collision>
        <inertial>
            <origin xyz="0 0 0" rpy="0 0 0"/>
            <mass value="0.477"/>
            <inertia
            ixx="0.0013" ixy="0" ixz="0"
            iyy="0.0024" iyz="0"
            izz="0.0013"/>
      </inertial>
    </link>

    <joint name="wheel_front_right_joint" type="continuous">
      <parent link="chassis_link" />
      <child link="wheel_front_right_link" />
      <origin rpy="0 0 0" xyz="0.131 -0.187795 0.0345" />
      <axis xyz="0 1 0" />
    </joint>

    <!-- Front left wheel -->

    <link name="wheel_front_left_link">
        <visual>
            <origin xyz="0 0 0" rpy="1.57 0 0"/>
            <geometry>
                <mesh filename="package://jackal_playground/meshes/jackal-wheel.stl"/>
            </geometry>
            <material name="black" />
        </visual>
        <collision>
            <origin xyz="0 0 0" rpy="1.57 0 0"/>
            <geometry>
                <cylinder radius="0.098" length="0.040"/>
            </geometry>
        </collision>
        <inertial>
            <origin xyz="0 0 0" rpy="0 0 0"/>
            <mass value="0.477"/>
            <inertia
            ixx="0.0013" ixy="0" ixz="0"
            iyy="0.0024" iyz="0"
            izz="0.0013"/>
      </inertial>
    </link>

    <joint name="wheel_front_left_joint" type="continuous">
      <parent link="chassis_link" />
      <child link="wheel_front_left_link" />
      <origin rpy="0 0 0" xyz="0.131 0.187795 0.0345" />
      <axis xyz="0 1 0" />
    </joint>

    <!-- Back right wheel -->

    <link name="wheel_back_right_link">
        <visual>
            <origin xyz="0 0 0" rpy="1.57 0 0"/>
            <geometry>
                <mesh filename="package://jackal_playground/meshes/jackal-wheel.stl"/>
            </geometry>
            <material name="black" />
        </visual>
        <collision>
            <origin xyz="0 0 0" rpy="1.57 0 0"/>
            <geometry>
                <cylinder radius="0.098" length="0.040"/>
            </geometry>
        </collision>
        <inertial>
            <origin xyz="0 0 0" rpy="0 0 0"/>
            <mass value="0.477"/>
            <inertia
            ixx="0.0013" ixy="0" ixz="0"
            iyy="0.0024" iyz="0"
            izz="0.0013"/>
      </inertial>
    </link>

    <joint name="wheel_back_right_joint" type="continuous">
      <parent link="chassis_link" />
      <child link="wheel_back_right_link" />
      <origin rpy="0 0 0" xyz="-0.131 -0.187795 0.0345" />
      <axis xyz="0 1 0" />
    </joint>

    <!-- Back left wheel -->

    <link name="wheel_back_left_link">
        <visual>
            <origin xyz="0 0 0" rpy="1.57 0 0"/>
            <geometry>
                <mesh filename="package://jackal_playground/meshes/jackal-wheel.stl"/>
            </geometry>
            <material name="black" />
        </visual>
        <collision>
            <origin xyz="0 0 0" rpy="1.57 0 0"/>
            <geometry>
                <cylinder radius="0.098" length="0.040"/>
            </geometry>
        </collision>
        <inertial>
            <origin xyz="0 0 0" rpy="0 0 0"/>
            <mass value="0.477"/>
            <inertia
            ixx="0.0013" ixy="0" ixz="0"
            iyy="0.0024" iyz="0"
            izz="0.0013"/>
      </inertial>
    </link>

    <joint name="wheel_back_left_joint" type="continuous">
      <parent link="chassis_link" />
      <child link="wheel_back_left_link" />
      <origin rpy="0 0 0" xyz="-0.131 0.187795 0.0345" />
      <axis xyz="0 1 0" />
    </joint>

</robot>